<body bgcolor="#f0f0f8">
<table width="100%" cellspacing=0 cellpadding=2 border=0 summary="heading">
<tr bgcolor="#6622aa">
<td valign=bottom>&nbsp;<br>
<font color="#ffffff" face="helvetica, arial">&nbsp;<br><big><big><strong>&lt;type 'exceptions.IndexError'&gt;</strong></big></big></font></td
><td align=right valign=bottom
><font color="#ffffff" face="helvetica, arial">Python 2.7.6: /usr/bin/python<br>Mon Jul  4 18:03:17 2016</font></td></tr></table>
    
<p>A problem occurred in a Python script.  Here is the sequence of
function calls leading up to the error, in the order they occurred.</p>
<table width="100%" cellspacing=0 cellpadding=0 border=0>
<tr><td bgcolor="#d8bbff"><big>&nbsp;</big><a href="file:///var/www/html/final_3/license.py">/var/www/html/final_3/license.py</a> in <strong><module></strong>()</td></tr>
<tr><td><font color="#909090"><tt>&nbsp;&nbsp;<small>&nbsp;&nbsp;&nbsp;67</small>&nbsp;dl_no1=dl_no.split()<br>
</tt></font></td></tr>
<tr><td><font color="#909090"><tt>&nbsp;&nbsp;<small>&nbsp;&nbsp;&nbsp;68</small>&nbsp;#print&nbsp;dl_no1<br>
</tt></font></td></tr>
<tr><td bgcolor="#ffccee"><tt>=&gt;<small>&nbsp;&nbsp;&nbsp;69</small>&nbsp;dl_no2=[dl_no1[0]+dl_no1[1]]<br>
</tt></td></tr>
<tr><td><font color="#909090"><tt>&nbsp;&nbsp;<small>&nbsp;&nbsp;&nbsp;70</small>&nbsp;#print&nbsp;dl_no2&nbsp;#licence&nbsp;number&nbsp;in&nbsp;better&nbsp;format<br>
</tt></font></td></tr>
<tr><td><font color="#909090"><tt>&nbsp;&nbsp;<small>&nbsp;&nbsp;&nbsp;71</small>&nbsp;print&nbsp;"hello"<br>
</tt></font></td></tr>
<tr><td><small><font color="#909090">dl_no2 <em>undefined</em>, <strong>dl_no1</strong>&nbsp;= []</font></small></td></tr></table><p><strong>&lt;type 'exceptions.IndexError'&gt;</strong>: list index out of range
<br><tt><small>&nbsp;&nbsp;&nbsp;&nbsp;&nbsp;</small>&nbsp;</tt>args&nbsp;=
('list index out of range',)
<br><tt><small>&nbsp;&nbsp;&nbsp;&nbsp;&nbsp;</small>&nbsp;</tt>message&nbsp;=
'list index out of range'


<!-- The above is a description of an error in a Python program, formatted
     for a Web browser because the 'cgitb' module was enabled.  In case you
     are not reading this in a Web browser, here is the original traceback:

Traceback (most recent call last):
  File "license.py", line 69, in &lt;module&gt;
    dl_no2=[dl_no1[0]+dl_no1[1]]
IndexError: list index out of range

-->
